#VRML_SIM R2023a utf8

EXTERNPROTO "https://raw.githubusercontent.com/cyberbotics/webots/R2023a/projects/objects/trees/protos/BigSassafras.proto"
EXTERNPROTO "https://raw.githubusercontent.com/cyberbotics/webots/R2023a/projects/objects/trees/protos/Cypress.proto"
EXTERNPROTO "https://raw.githubusercontent.com/cyberbotics/webots/R2023a/projects/appearances/protos/DryMud.proto"
EXTERNPROTO "https://raw.githubusercontent.com/cyberbotics/webots/R2023a/projects/objects/trees/protos/Oak.proto"
EXTERNPROTO "https://raw.githubusercontent.com/cyberbotics/webots/R2023a/projects/appearances/protos/PaintedWood.proto"
EXTERNPROTO "https://raw.githubusercontent.com/cyberbotics/webots/R2023a/projects/objects/trees/protos/Pine.proto"
EXTERNPROTO "https://raw.githubusercontent.com/cyberbotics/webots/R2023a/projects/appearances/protos/Rubber.proto"
EXTERNPROTO "https://raw.githubusercontent.com/cyberbotics/webots/R2023a/projects/objects/trees/protos/SimpleTree.proto"
EXTERNPROTO "https://raw.githubusercontent.com/cyberbotics/webots/R2023a/projects/objects/backgrounds/protos/TexturedBackground.proto"
EXTERNPROTO "https://raw.githubusercontent.com/cyberbotics/webots/R2023a/projects/objects/backgrounds/protos/TexturedBackgroundLight.proto"
EXTERNPROTO "https://raw.githubusercontent.com/cyberbotics/webots/R2023a/projects/objects/floors/protos/UnevenTerrain.proto"

WorldInfo {
}
Viewpoint {
  orientation -0.21014280679097047 0.1826072991329562 0.960465811498452 1.7506192431806922
  position 3.2890193814152346 -25.71731589609079 18.39196430603637
}
TexturedBackground {
}
TexturedBackgroundLight {
}
Robot {
  translation 3.118924224027678 -3.1417305693778816 4.034202941340192
  rotation 0.08698970885003923 0.011412220147670439 -0.9961438409112846 1.4783335207231767
  children [
    DEF base Shape {
      appearance PaintedWood {
        colorOverride 0 0.2 0.1
      }
      geometry DEF Base Box {
        size 1.2 3 1
      }
    }
    DEF wheel1 HingeJoint {
      jointParameters HingeJointParameters {
        position -20.727783210876552
        anchor 0.75 -0.96 -0.53
      }
      device [
        RotationalMotor {
          name "wheel1"
          maxTorque 40
        }
      ]
      endPoint Solid {
        translation 0.75 -0.96 -0.53
        rotation 0.6280237077353649 -0.45952669411757174 0.6280298081426556 4.003082928759934
        children [
          DEF wheel Shape {
            appearance Rubber {
            }
            geometry Cylinder {
              height 0.5
              radius 0.5
            }
          }
        ]
        boundingObject USE wheel
        physics DEF phy1 Physics {
          mass 1
        }
        linearVelocity -1.2655167898190173e-05 -1.225921675575624e-05 -2.149255800191473e-06
        angularVelocity 1.616558725728976e-07 -2.338234084154002e-09 -8.206693371017667e-08
      }
    }
    DEF wheel2 HingeJoint {
      jointParameters HingeJointParameters {
        position -45.164704362487306
        anchor -0.75 -0.96 -0.53
      }
      device [
        RotationalMotor {
          name "wheel2"
          maxTorque 40
        }
      ]
      endPoint Solid {
        translation -0.75 -0.96 -0.53
        rotation 0.4868432956362365 -0.7252325463741753 0.4868483944450032 4.396505961717361
        children [
          DEF wheel Shape {
            appearance Rubber {
            }
            geometry Cylinder {
              height 0.5
              radius 0.5
            }
          }
        ]
        name "solid(1)"
        boundingObject USE wheel
        physics USE phy1
        linearVelocity -1.2533226716968284e-05 -1.2268941209225248e-05 -1.909767799021441e-06
        angularVelocity 1.0684307539191083e-06 -9.060072536333e-06 -9.047734737872125e-07
      }
    }
    DEF wheel3 HingeJoint {
      jointParameters HingeJointParameters {
        position -30.51904741541404
        anchor 0.75 0.96 -0.53
      }
      device [
        RotationalMotor {
          name "wheel3"
          maxTorque 40
        }
      ]
      endPoint Solid {
        translation 0.75 0.96 -0.53
        rotation -0.3977803946745836 -0.8267643753832326 -0.39778313841804047 4.5232812972375855
        children [
          DEF wheel Shape {
            appearance Rubber {
            }
            geometry Cylinder {
              height 0.5
              radius 0.5
            }
          }
        ]
        name "solid(2)"
        boundingObject USE wheel
        physics USE phy1
        linearVelocity -1.2641167541073828e-05 -1.243915143162864e-05 -2.116313470707958e-06
        angularVelocity 1.0775775187931064e-06 -9.151546118685353e-06 -9.131732838890244e-07
      }
    }
    DEF wheel4 HingeJoint {
      jointParameters HingeJointParameters {
        position -49.85886537545911
        anchor -0.75 0.96 -0.53
      }
      device [
        RotationalMotor {
          name "wheel4"
          maxTorque 40
        }
      ]
      endPoint Solid {
        translation -0.75 0.96 -0.53
        rotation 0.1979163516744103 0.960030162413069 0.1979171670094026 1.6115847749549144
        children [
          DEF wheel Shape {
            appearance Rubber {
            }
            geometry Cylinder {
              height 0.5
              radius 0.5
            }
          }
        ]
        name "solid(3)"
        boundingObject USE wheel
        physics USE phy1
        linearVelocity -1.2519250594993832e-05 -1.2448917518174252e-05 -1.8764344463880454e-06
        angularVelocity 1.6160715912878444e-07 -2.3359499270392016e-09 -8.206977202978831e-08
      }
    }
  ]
  boundingObject USE base
  physics USE phy1
  controller "explorer_controller"
  linearVelocity -1.2592649038205561e-05 -1.2436183171747217e-05 -2.021329007220629e-06
  angularVelocity 1.6160716065196142e-07 -2.3359497480570817e-09 -8.206977281526897e-08
}
DEF forest Solid {
  children [
    Pine {
      translation -15.62 20.85 1.15
      name "pine tree(6)"
    }
    Pine {
      translation -15.62 -10.45 1.15
      name "pine tree(5)"
    }
    Pine {
      translation 11.67 -10.45 1.45
      name "pine tree(3)"
    }
    Pine {
      translation 20.49 -10.45 2.81
      name "pine tree(4)"
    }
    Pine {
      translation 11.67 15.84 1.88
      name "pine tree(2)"
    }
    Pine {
      translation -4.35 9.25 2.22
      name "pine tree(1)"
    }
    Pine {
      translation -4.35 -3.53 2.18
    }
    SimpleTree {
      translation 0 0 3
    }
    SimpleTree {
      translation 6 0 3
      name "tree(1)"
    }
    SimpleTree {
      translation 6 10 3
      name "tree(2)"
    }
    SimpleTree {
      translation 16 15 3
      name "tree(3)"
    }
    SimpleTree {
      translation -16 -15 1.8
      name "tree(4)"
    }
    SimpleTree {
      translation 16 -15 3
      name "tree(5)"
    }
    SimpleTree {
      translation 5 -22 2
      name "tree(6)"
    }
    SimpleTree {
      translation -15 -22 2
      name "tree(7)"
    }
    SimpleTree {
      translation -9 22 2
      name "tree(8)"
    }
    SimpleTree {
      translation -18 16 2.5
      name "tree(9)"
    }
    SimpleTree {
      translation -22 -3 2
      name "tree(10)"
    }
    SimpleTree {
      translation 10 -8 3
      name "tree(11)"
    }
    SimpleTree {
      translation -5 -8 2.3
      name "tree(12)"
    }
    SimpleTree {
      translation 1 -17 2
      name "tree(13)"
    }
    Oak {
      translation 14.94 0 3.24
    }
    Oak {
      translation 20 -5.97 3.28
      name "oak tree(1)"
    }
    Oak {
      translation 15.97 -10.75 3.02
      name "oak tree(2)"
    }
    Oak {
      translation 15.97 11.04 3.07
      name "oak tree(3)"
    }
    Oak {
      translation -24.52 6.27 2.46
      name "oak tree(4)"
    }
    Oak {
      translation -12.06 2.39 2.09
      name "oak tree(6)"
    }
    Oak {
      translation -13.84 10.96 2.09
      name "oak tree(7)"
    }
    Oak {
      translation -2.97 18.97 1.79
      name "oak tree(8)"
    }
    Oak {
      translation 0.35 13.07 2.24
      name "oak tree(9)"
    }
    Oak {
      translation -9.22 15.64 2.72
      name "oak tree(5)"
    }
    Oak {
      translation 7.46 20.45 2.43
      name "oak tree(10)"
    }
    Oak {
      translation 16.74 21.4 2.43
      name "oak tree(11)"
    }
    BigSassafras {
      translation -11.82 -13.71 1.72
    }
    BigSassafras {
      translation -21.32 -8.95 1.72
      name "sassafras tree(1)"
    }
    BigSassafras {
      translation 19.67 7.95 3.44
      name "sassafras tree(2)"
    }
    BigSassafras {
      translation 19.67 -1.13 2.97
      name "sassafras tree(3)"
    }
    BigSassafras {
      translation 21.66 -19.93 2.97
      name "sassafras tree(4)"
    }
    BigSassafras {
      translation 9.84 -19.93 2.64
      name "sassafras tree(5)"
    }
    BigSassafras {
      translation -6.69 -19.93 1.29
      name "sassafras tree(6)"
    }
    BigSassafras {
      translation -16.82 -5.16 2.98
      name "sassafras tree(7)"
    }
    BigSassafras {
      translation -16.82 8.12 2.98
      name "sassafras tree(8)"
    }
    BigSassafras {
      translation -21.82 21.14 2.98
      name "sassafras tree(9)"
    }
    BigSassafras {
      translation 1.95 21.14 2.63
      name "sassafras tree(10)"
    }
    Cypress {
      translation -11.36 0 1.96
    }
    Cypress {
      translation -14.16 5.78 2.06
      name "cypress tree(1)"
    }
    Cypress {
      translation 20.42 15.8 3.01
      name "cypress tree(2)"
    }
    Cypress {
      translation 21.87 20.79 3.01
      name "cypress tree(3)"
    }
    Cypress {
      translation 11.51 1.81 3.01
      name "cypress tree(4)"
    }
    Cypress {
      translation 2.77 -10.75 2.51
      name "cypress tree(5)"
    }
    Cypress {
      translation -2.24 -21.57 1.87
      name "cypress tree(6)"
    }
    Cypress {
      translation 15.22 -21.57 2.5
      name "cypress tree(7)"
    }
    Cypress {
      translation 6.61 -15.53 2.8
      name "cypress tree(8)"
    }
    Cypress {
      translation -11.26 5.51 2.26
      name "cypress tree(9)"
    }
  ]
}
UnevenTerrain {
}
DEF Border Solid {
  translation 0 0 3.9
  children [
    Solid {
      translation 0 -25.2 -0.37003136092665656
      children [
        DEF border Shape {
          appearance DryMud {
          }
          geometry Box {
            size 49 1 3
          }
        }
      ]
      name "border1"
      boundingObject USE border
      physics DEF phy1 Physics {
        mass 1
      }
      linearVelocity 0 0 -1.2139209860606136e-07
    }
    Solid {
      translation 0 25.53 -0.37003136092665656
      children [
        DEF border Shape {
          appearance DryMud {
          }
          geometry Box {
            size 49 1 3
          }
        }
      ]
      name "border2"
      boundingObject USE border
      physics USE phy1
      linearVelocity 0 0 -1.2139209860606136e-07
    }
    Solid {
      translation 25.53 0 -0.37
      rotation 0 0 1 1.5708
      children [
        DEF border Shape {
          appearance DryMud {
          }
          geometry Box {
            size 49 1 3
          }
        }
      ]
      name "border3"
      boundingObject USE border
    }
    Solid {
      translation -25.5301 1.57462e-05 -0.37003136092665656
      rotation 5.1580022398749126e-05 -9.550089548459884e-05 0.9999999941095401 1.569814080916819
      children [
        DEF border Shape {
          appearance DryMud {
          }
          geometry Box {
            size 49 1 3
          }
        }
      ]
      name "border4"
      boundingObject USE border
      physics USE phy1
      linearVelocity 0 0 -1.2139209860606136e-07
    }
  ]
  name "solid(1)"
}
